OrderBookSim/OrderBookSim/Outputs/Log1359732954.txt
0--INFO	Added rule
0--INFO	Added rule
0--INFO	Added rule
0--INFO	Added rule
0--INFO	Added trader: Trader[0]: Cash[$1798.76], Holding:GOOG[9636], PositionCash[$1798.76], PositionHolding:GOOG[9636]
0--INFO	Added trader: Trader[1]: Cash[$5206.46], Holding:GOOG[12775], PositionCash[$5206.46], PositionHolding:GOOG[12775]
0--INFO	Added trader: Trader[2]: Cash[$12297.13], Holding:GOOG[15773], PositionCash[$12297.13], PositionHolding:GOOG[15773]
0--INFO	Added trader: Trader[3]: Cash[$11741.69], Holding:GOOG[15326], PositionCash[$11741.69], PositionHolding:GOOG[15326]
0--INFO	Added trader: Trader[4]: Cash[$18057.80], Holding:GOOG[8286], PositionCash[$18057.80], PositionHolding:GOOG[8286]
0--INFO	Added trader: Trader[5]: Cash[$12533.95], Holding:GOOG[12840], PositionCash[$12533.95], PositionHolding:GOOG[12840]
0--INFO	Added trader: Trader[6]: Cash[$12566.30], Holding:GOOG[11157], PositionCash[$12566.30], PositionHolding:GOOG[11157]
0--INFO	Added trader: Trader[7]: Cash[$4636.98], Holding:GOOG[10470], PositionCash[$4636.98], PositionHolding:GOOG[10470]
0--INFO	Added trader: Trader[8]: Cash[$2085.02], Holding:GOOG[6419], PositionCash[$2085.02], PositionHolding:GOOG[6419]
0--INFO	Added trader: Trader[9]: Cash[$12332.53], Holding:GOOG[19505], PositionCash[$12332.53], PositionHolding:GOOG[19505]
0--INFO	Added trader: Trader[10]: Cash[$18875.09], Holding:GOOG[16911], PositionCash[$18875.09], PositionHolding:GOOG[16911]
0--INFO	Added trader: Trader[11]: Cash[$15546.74], Holding:GOOG[6732], PositionCash[$15546.74], PositionHolding:GOOG[6732]
0--INFO	Added trader: Trader[12]: Cash[$8468.28], Holding:GOOG[9995], PositionCash[$8468.28], PositionHolding:GOOG[9995]
0--INFO	Added trader: Trader[13]: Cash[$3131.81], Holding:GOOG[4827], PositionCash[$3131.81], PositionHolding:GOOG[4827]
0--INFO	Added trader: Trader[14]: Cash[$7369.00], Holding:GOOG[8142], PositionCash[$7369.00], PositionHolding:GOOG[8142]
0--INFO	Added trader: Trader[15]: Cash[$14236.88], Holding:GOOG[9104], PositionCash[$14236.88], PositionHolding:GOOG[9104]
0--INFO	Added trader: Trader[16]: Cash[$9284.34], Holding:GOOG[7027], PositionCash[$9284.34], PositionHolding:GOOG[7027]
0--INFO	Added trader: Trader[17]: Cash[$3516.34], Holding:GOOG[8359], PositionCash[$3516.34], PositionHolding:GOOG[8359]
0--INFO	Added trader: Trader[18]: Cash[$19460.43], Holding:GOOG[17443], PositionCash[$19460.43], PositionHolding:GOOG[17443]
0--INFO	Added trader: Trader[19]: Cash[$6925.87], Holding:GOOG[14618], PositionCash[$6925.87], PositionHolding:GOOG[14618]
0--INFO	Added trader: Trader[20]: Cash[$10322.58], Holding:GOOG[6428], PositionCash[$10322.58], PositionHolding:GOOG[6428]
0--INFO	Added trader: Trader[21]: Cash[$16730.86], Holding:GOOG[824], PositionCash[$16730.86], PositionHolding:GOOG[824]
0--INFO	Added trader: Trader[22]: Cash[$9936.22], Holding:GOOG[18059], PositionCash[$9936.22], PositionHolding:GOOG[18059]
0--INFO	Added trader: Trader[23]: Cash[$19744.25], Holding:GOOG[19491], PositionCash[$19744.25], PositionHolding:GOOG[19491]
0--INFO	Added trader: Trader[24]: Cash[$10308.54], Holding:GOOG[7832], PositionCash[$10308.54], PositionHolding:GOOG[7832]
0--INFO	Added trader: Trader[25]: Cash[$14075.75], Holding:GOOG[11435], PositionCash[$14075.75], PositionHolding:GOOG[11435]
0--INFO	Added trader: Trader[26]: Cash[$7769.40], Holding:GOOG[8958], PositionCash[$7769.40], PositionHolding:GOOG[8958]
0--INFO	Added trader: Trader[27]: Cash[$19407.94], Holding:GOOG[14572], PositionCash[$19407.94], PositionHolding:GOOG[14572]
0--INFO	Added trader: Trader[28]: Cash[$15013.28], Holding:GOOG[6769], PositionCash[$15013.28], PositionHolding:GOOG[6769]
0--INFO	Added trader: Trader[29]: Cash[$16470.23], Holding:GOOG[706], PositionCash[$16470.23], PositionHolding:GOOG[706]
0--INFO	Added trader: Trader[30]: Cash[$6496.78], Holding:GOOG[11200], PositionCash[$6496.78], PositionHolding:GOOG[11200]
0--INFO	Added trader: Trader[31]: Cash[$15507.68], Holding:GOOG[16004], PositionCash[$15507.68], PositionHolding:GOOG[16004]
0--INFO	Added trader: Trader[32]: Cash[$8117.92], Holding:GOOG[9563], PositionCash[$8117.92], PositionHolding:GOOG[9563]
0--INFO	Added trader: Trader[33]: Cash[$1798.76], Holding:GOOG[9636], PositionCash[$1798.76], PositionHolding:GOOG[9636]
0--INFO	Added trader: Trader[34]: Cash[$1798.76], Holding:GOOG[9636], PositionCash[$1798.76], PositionHolding:GOOG[9636]
0--INFO	Added trader: Trader[35]: Cash[$1798.76], Holding:GOOG[9636], PositionCash[$1798.76], PositionHolding:GOOG[9636]
0--INFO	Added trader: Trader[36]: Cash[$1798.76], Holding:GOOG[9636], PositionCash[$1798.76], PositionHolding:GOOG[9636]
0--INFO	Added trader: Trader[37]: Cash[$1798.76], Holding:GOOG[9636], PositionCash[$1798.76], PositionHolding:GOOG[9636]
0--INFO	Added trader: Trader[38]: Cash[$1798.76], Holding:GOOG[9636], PositionCash[$1798.76], PositionHolding:GOOG[9636]
0--INFO	Added trader: Trader[39]: Cash[$1798.76], Holding:GOOG[9636], PositionCash[$1798.76], PositionHolding:GOOG[9636]
0--INFO	Added trader: Trader[40]: Cash[$1798.76], Holding:GOOG[9636], PositionCash[$1798.76], PositionHolding:GOOG[9636]
0--INFO	Added trader: Trader[41]: Cash[$1798.76], Holding:GOOG[9636], PositionCash[$1798.76], PositionHolding:GOOG[9636]
0--INFO	Added trader: Trader[42]: Cash[$1798.76], Holding:GOOG[9636], PositionCash[$1798.76], PositionHolding:GOOG[9636]
0--INFO	Added trader: Trader[43]: Cash[$1798.76], Holding:GOOG[9636], PositionCash[$1798.76], PositionHolding:GOOG[9636]
0--INFO	Added trader: Trader[44]: Cash[$1798.76], Holding:GOOG[9636], PositionCash[$1798.76], PositionHolding:GOOG[9636]
0--INFO	Added trader: Trader[45]: Cash[$1798.76], Holding:GOOG[9636], PositionCash[$1798.76], PositionHolding:GOOG[9636]
0--INFO	Added trader: Trader[46]: Cash[$1798.76], Holding:GOOG[9636], PositionCash[$1798.76], PositionHolding:GOOG[9636]
0--INFO	Added trader: Trader[47]: Cash[$1798.76], Holding:GOOG[9636], PositionCash[$1798.76], PositionHolding:GOOG[9636]
0--INFO	Added trader: Trader[48]: Cash[$1000000.00], Holding:GOOG[10000000], PositionCash[$1000000.00], PositionHolding:GOOG[10000000]
0--INFO	Added trader: Trader[49]: Cash[$1000000.00], Holding:GOOG[10000000], PositionCash[$1000000.00], PositionHolding:GOOG[10000000]
38--INFO	Enqueued order: Price: 0.96, Volume: 123, Type: BUY, Market Order: 0, Participant: 32, Stock:[ID: 0, Symbol: GOOG], Time: 38, OrderNumber: 0
59--INFO	Enqueued order: Price: 0.00, Volume: 615, Type: SELL, Market Order: 1, Participant: 33, Stock:[ID: 0, Symbol: GOOG], Time: 59, OrderNumber: 1
59--INFO	Enqueued order: Price: 2147483647.00, Volume: 767, Type: BUY, Market Order: 1, Participant: 34, Stock:[ID: 0, Symbol: GOOG], Time: 59, OrderNumber: 2
59--INFO	Enqueued order: Price: 0.00, Volume: 624, Type: SELL, Market Order: 1, Participant: 35, Stock:[ID: 0, Symbol: GOOG], Time: 59, OrderNumber: 3
59--INFO	Enqueued order: Price: 2147483647.00, Volume: 629, Type: BUY, Market Order: 1, Participant: 36, Stock:[ID: 0, Symbol: GOOG], Time: 59, OrderNumber: 4
59--INFO	Enqueued order: Price: 0.98, Volume: 524, Type: BUY, Market Order: 0, Participant: 37, Stock:[ID: 0, Symbol: GOOG], Time: 59, OrderNumber: 5
59--INFO	Enqueued order: Price: 1.03, Volume: 190, Type: SELL, Market Order: 0, Participant: 38, Stock:[ID: 0, Symbol: GOOG], Time: 59, OrderNumber: 6
59--INFO	Enqueued order: Price: 2147483647.00, Volume: 944, Type: BUY, Market Order: 1, Participant: 39, Stock:[ID: 0, Symbol: GOOG], Time: 59, OrderNumber: 7
59--INFO	Enqueued order: Price: 0.93, Volume: 337, Type: BUY, Market Order: 0, Participant: 40, Stock:[ID: 0, Symbol: GOOG], Time: 59, OrderNumber: 8
59--INFO	Enqueued order: Price: 2147483647.00, Volume: 969, Type: BUY, Market Order: 1, Participant: 41, Stock:[ID: 0, Symbol: GOOG], Time: 59, OrderNumber: 9
59--INFO	Enqueued order: Price: 0.00, Volume: 369, Type: SELL, Market Order: 1, Participant: 42, Stock:[ID: 0, Symbol: GOOG], Time: 59, OrderNumber: 10
59--INFO	Enqueued order: Price: 0.00, Volume: 456, Type: SELL, Market Order: 1, Participant: 43, Stock:[ID: 0, Symbol: GOOG], Time: 59, OrderNumber: 11
